Workbook

Sheet Index
B2: Asian Paints Ltd
B3: ASIANPAINT | 500820
B4: Index
B6: Inputs
B7: Historical Financial Statement
B8: Market Data
B9: Assumptions
B11: Calculation & Analysis
B12: Income Statement
B13: Balance Sheet
B14: Cash Flow Statement
B15: Working Capital
... B25: Comparables Analysis

Sheet Assumption
B2: Asian Paints Ltd
B3: ASIANPAINT | 500820
B4: Assumption
B6: Company Name | C6: Asian Paint ltd
B7: ISIN Code | C7: INE021A01026
B8: Sector Name | C8: Building Materials
B9: Industry | C9: Manufacturing
B10: Basic Industry | C10: Paints & Varnishes
B11: Exchange Name | C11: BSE: 500820, NSE: ASIANPAINT
B12: Website | C12: https://www.asianpaints.com
B13: Company Description | C13: Asian Paints Ltd. is India’s leading paint and décor company, engaged in the manufacturing and sale of decorative and industrial paints, coatings, and home décor products. The company offers products such as interior and exterior paints, waterproofing solutions, wood finishes, adhesives, and wall coverings. It has a strong distribution network across India and also operates in several international markets.
B14: Current Market Price | C14: 2640
B17: Company data
B18: Particulars
B19: No of Outstanding shares | C19: Nos | D19: 959172430
B20: Face Value per share | C20: Rs. | D20: 1
B21: Current Market Price | C21: Rs. | D21: 2640
B22: Market Capitalisation | C22: Rs. | D22: 253228
B24: Assumptions
B25: Increase in Revenue growth rate | C25: % | D25: =Scenario!D8 -> 0.054753391
B26: Base Case | C26: % | D26: =D25 -> 0.054753391
B27: Bull Case | C27: % | D27: =Scenario!D9 -> 0.18512278
B28: Base Case | C28: % | D28: =Scenario!F10 -> 0.05
B29: Perpetual Growth rate | C29: % | D29: =Model!C155 -> 0.07
B30: 5 year Bond yield rate | C30: % | D30: =WACC!D44 -> 0.0676
B31: Interest rate | C31: % | D31: =WACC!D39 -> 0.26210735
B32: Annual Growth Tapering | C32: % | D32: =Scenario!D11 -> 0.095
B33: WACC | C33: % | D33: =WACC!D50 -> 0.078523981

Sheet Model
B2: Asian Paints Ltd
B3: ASIANPAINT | 500820 | E3: Historical Period
B4: Financial Statement & DCF Analysis | E4: 2022 | F4: =E4+1 -> 2023 | G4: =F4+1 -> 2024 | H4: =G4+1 -> 2025 | I4: =H4+1 -> 2026 | J4: =I4+1 -> 2027 | K4: =J4+1 -> 2028 | L4: =K4+1 -> 2029 | M4: =L4+1 -> 2030 | ... S4: =R4+1 -> 2036
B5: MasterCheck | E5: =IF(E94=0,"Ok","Error") -> Ok | F5: =IF(F94=0,"Ok","Error") -> Ok | G5: =IF(G94=0,"Ok","Error") -> Ok | H5: =IF(H94=0,"Ok","Error") -> Ok | I5: =IF(I94=0,"Ok","Error") -> Ok | J5: =IF(J94=0,"Ok","Error") -> Ok | K5: =IF(K94=0,"Ok","Error") -> Ok | L5: =IF(L94=0,"Ok","Error") -> Ok | ... S5: =IF(S94=0,"Ok","Error") -> Ok
B6: All Values In Crores
B8: Ratio & Assumptions
B10: Live Scenario | D10: Units | E10: 1
B12: Revenue Growth | D12: % | E12: 0 | F12: =F30/E30-1 -> 0.18512278 | G12: =G30/F30-1 -> 0.029173127 | H12: =H30/G30-1 -> -0.044770308 | I12: =I30/H30-1 -> 0.049487961 | J12: {=CHOOSE(E10,Scenario!F8:O8,Scenario!F9:O9,Scenario!F10:O10)} -> 0.057753391 | K12: 0.060753391 | L12: 0.063753391 | M12: 0.066753391 | N12: 0.069753391 | O12: 0.072753391 | P12: 0.075753391 | Q12: 0.078753391 | R12: 0.081753391 | S12: 0.084753391
B13: Cost of Good Sold (% of Revenue) | D13: % | E13: =-E31/E30 -> 0.62886409 | F13: =-F31/F30 -> 0.61343476 | G13: =-G31/G30 -> 0.56600543 | H13: =-H31/H30 -> 0.5755913 | I13: =-I31/I30 -> 0.56210765 | J13: =AVERAGE($E13:$I13) -> 0.58920065 | K13: =AVERAGE($E13:$I13) -> 0.58920065 | L13: =AVERAGE($E13:$I13) -> 0.58920065 | M13: =AVERAGE($E13:$I13) -> 0.58920065 | N13: =AVERAGE($E13:$I13) -> 0.58920065 | O13: =AVERAGE($E13:$I13) -> 0.58920065 | P13: =AVERAGE($E13:$I13) -> 0.58920065 | Q13: =AVERAGE($E13:$I13) -> 0.58920065 | ... S13: =AVERAGE($E13:$I13) -> 0.58920065
B14: Employee Benefits Expenses (% of Revenue) | D14: % | E14: =-E36/E30 -> 0.061394894 | F14: =-F36/F30 -> 0.058804086 | G14: =-G36/G30 -> 0.065535926 | H14: =-H36/H30 -> 0.076601755 | I14: =-I36/I30 -> 0.078676545 | J14: =AVERAGE($E14:$I14) -> 0.068202641 | K14: =AVERAGE($E14:$I14) -> 0.068202641 | L14: =AVERAGE($E14:$I14) -> 0.068202641 | M14: =AVERAGE($E14:$I14) -> 0.068202641 | N14: =AVERAGE($E14:$I14) -> 0.068202641 | O14: =AVERAGE($E14:$I14) -> 0.068202641 | P14: =AVERAGE($E14:$I14) -> 0.068202641 | Q14: =AVERAGE($E14:$I14) -> 0.068202641 | ... S14: =AVERAGE($E14:$I14) -> 0.068202641
B15: Other SG&A Expenses (% of Revenue) | D15: % | E15: =-E37/E30 -> 0.14467577 | F15: =-F37/F30 -> 0.14625649 | G15: =-G37/G30 -> 0.15476551 | H15: =-H37/H30 -> 0.17066197 | I15: =-I37/I30 -> 0.17104116 | J15: =AVERAGE($E15:$I15) -> 0.15748018 | K15: =AVERAGE($E15:$I15) -> 0.15748018 | L15: =AVERAGE($E15:$I15) -> 0.15748018 | M15: =AVERAGE($E15:$I15) -> 0.15748018 | N15: =AVERAGE($E15:$I15) -> 0.15748018 | O15: =AVERAGE($E15:$I15) -> 0.15748018 | P15: =AVERAGE($E15:$I15) -> 0.15748018 | Q15: =AVERAGE($E15:$I15) -> 0.15748018 | ... S15: =AVERAGE($E15:$I15) -> 0.15748018
B16: Depreciation & Amortisation Expenses (% of PPE) | D16: % | E16: 0 | F16: =-F40/F137 -> 0.15546488 | G16: =-G40/G137 -> 0.14782184 | H16: =-H40/H137 -> 0.14361195 | I16: =-I40/I137 -> 0.13327947 | J16: =AVERAGE($E16:$I16) -> 0.11603563 | K16: =AVERAGE($E16:$I16) -> 0.11603563 | L16: =AVERAGE($E16:$I16) -> 0.11603563 | M16: =AVERAGE($E16:$I16) -> 0.11603563 | N16: =AVERAGE($E16:$I16) -> 0.11603563 | O16: =AVERAGE($E16:$I16) -> 0.11603563 | P16: =AVERAGE($E16:$I16) -> 0.11603563 | Q16: =AVERAGE($E16:$I16) -> 0.11603563 | ... S16: =AVERAGE($E16:$I16) -> 0.11603563
B17: Interest (% of Debt) | D17: % | E17: 0 | F17: =-F43/F143 -> 0.091027677 | G17: =-G43/G143 -> 0.10616158 | H17: =-H43/H143 -> 0.091748236 | I17: =-I43/I143 -> 0.085321073 | J17: =AVERAGE($E17:$I17) -> 0.074851714 | K17: =AVERAGE($E17:$I17) -> 0.074851714 | L17: =AVERAGE($E17:$I17) -> 0.074851714 | M17: =AVERAGE($E17:$I17) -> 0.074851714 | N17: =AVERAGE($E17:$I17) -> 0.074851714 | O17: =AVERAGE($E17:$I17) -> 0.074851714 | P17: =AVERAGE($E17:$I17) -> 0.074851714 | Q17: =AVERAGE($E17:$I17) -> 0.074851714 | ... S17: =AVERAGE($E17:$I17) -> 0.074851714
B18: Other Income (% of Revenue) | D18: % | E18: =E44/E30 -> 0.013058189 | F18: =F44/F30 -> 0.011206025 | G18: =G44/G30 -> 0.019382032 | H18: =H44/H30 -> 0.016888351 | I18: =I44/I30 -> 0.020340865 | J18: =AVERAGE($E18:$I18) -> 0.016175092 | K18: =AVERAGE($E18:$I18) -> 0.016175092 | L18: =AVERAGE($E18:$I18) -> 0.016175092 | M18: =AVERAGE($E18:$I18) -> 0.016175092 | N18: =AVERAGE($E18:$I18) -> 0.016175092 | O18: =AVERAGE($E18:$I18) -> 0.016175092 | P18: =AVERAGE($E18:$I18) -> 0.016175092 | Q18: =AVERAGE($E18:$I18) -> 0.016175092 | ... S18: =AVERAGE($E18:$I18) -> 0.016175092
B19: Non - Operating Income (% of Revenue) | D19: % | E19: =E47/E30 -> 0.001084832 | F19: =F47/F30 -> 0.0027211898 | G19: =G47/G30 -> 0.0037470351 | H19: =H47/H30 -> 0.0041500495 | I19: =I47/I30 -> 0.0046535561 | J19: =AVERAGE($E19:$I19) -> 0.0032713325 | K19: =AVERAGE($E19:$I19) -> 0.0032713325 | L19: =AVERAGE($E19:$I19) -> 0.0032713325 | M19: =AVERAGE($E19:$I19) -> 0.0032713325 | N19: =AVERAGE($E19:$I19) -> 0.0032713325 | O19: =AVERAGE($E19:$I19) -> 0.0032713325 | P19: =AVERAGE($E19:$I19) -> 0.0032713325 | Q19: =AVERAGE($E19:$I19) -> 0.0032713325 | ... S19: =AVERAGE($E19:$I19) -> 0.0032713325
B20: Tax Rate (% of Earning Before Tax) | D20: % | E20: =-E51/E50 -> 0.26336766 | F20: =-F51/F50 -> 0.26253201 | G20: =-G51/G50 -> 0.24362221 | H20: =-H51/H50 -> 0.27304348 | I20: =-I51/I50 -> 0.26797136 | J20: =AVERAGE($E20:$I20) -> 0.26210735 | K20: =AVERAGE($E20:$I20) -> 0.26210735 | L20: =AVERAGE($E20:$I20) -> 0.26210735 | M20: =AVERAGE($E20:$I20) -> 0.26210735 | N20: =AVERAGE($E20:$I20) -> 0.26210735 | O20: =AVERAGE($E20:$I20) -> 0.26210735 | P20: =AVERAGE($E20:$I20) -> 0.26210735 | Q20: =AVERAGE($E20:$I20) -> 0.26210735 | ... S20: =AVERAGE($E20:$I20) -> 0.26210735
B21: Divident Payout | D21: % | E21: =-E118/E55 -> 0.57144524 | F21: =-F118/F55 -> 0.4614774 | G21: =-G118/G55 -> 0.45898206 | H21: =-H118/H55 -> 0.84648396 | I21: =-I118/I55 -> 0.55188876 | J21: =AVERAGE($E21:$I21) -> 0.57805548 | K21: =AVERAGE($E21:$I21) -> 0.57805548 | L21: =AVERAGE($E21:$I21) -> 0.57805548 | M21: =AVERAGE($E21:$I21) -> 0.57805548 | N21: =AVERAGE($E21:$I21) -> 0.57805548 | O21: =AVERAGE($E21:$I21) -> 0.57805548 | P21: =AVERAGE($E21:$I21) -> 0.57805548 | Q21: =AVERAGE($E21:$I21) -> 0.57805548 | ... S21: =AVERAGE($E21:$I21) -> 0.57805548
B22: Account Receivable | D22: Days | E22: =E63/E30*365 -> 48.587265 | F22: =F63/F30*365 -> 49.096677 | G22: =G63/G30*365 -> 50.293465 | H22: =H63/H30*365 -> 46.53097 | I22: =I63/I30*365 -> 45.822124 | J22: =AVERAGE($E22:$I22) -> 48.0661 | K22: =AVERAGE($E22:$I22) -> 48.0661 | L22: =AVERAGE($E22:$I22) -> 48.0661 | M22: =AVERAGE($E22:$I22) -> 48.0661 | N22: =AVERAGE($E22:$I22) -> 48.0661 | O22: =AVERAGE($E22:$I22) -> 48.0661 | P22: =AVERAGE($E22:$I22) -> 48.0661 | Q22: =AVERAGE($E22:$I22) -> 48.0661 | ... S22: =AVERAGE($E22:$I22) -> 48.0661
B23: Inventory | D23: Days | E23: =-E64/E31*365 -> 122.71834 | F23: =-F64/F31*365 -> 107.14833 | G23: =-G64/G31*365 -> 107.61683 | H23: =-H64/H31*365 -> 125.66926 | I23: =-I64/I31*365 -> 104.81301 | J23: =AVERAGE($E23:$I23) -> 113.59315 | K23: =AVERAGE($E23:$I23) -> 113.59315 | L23: =AVERAGE($E23:$I23) -> 113.59315 | M23: =AVERAGE($E23:$I23) -> 113.59315 | N23: =AVERAGE($E23:$I23) -> 113.59315 | O23: =AVERAGE($E23:$I23) -> 113.59315 | P23: =AVERAGE($E23:$I23) -> 113.59315 | Q23: =AVERAGE($E23:$I23) -> 113.59315 | ... S23: =AVERAGE($E23:$I23) -> 113.59315
B24: Accounts Payable | D24: Days | E24: =-E77/E31*365 -> 83.055039 | F24: =-F77/F31*365 -> 62.719996 | G24: =-G77/G31*365 -> 69.607988 | H24: =-H77/H31*365 -> 71.968428 | I24: =-I77/I31*365 -> 70.494206 | J24: =AVERAGE($E24:$I24) -> 71.569131 | K24: =AVERAGE($E24:$I24) -> 71.569131 | L24: =AVERAGE($E24:$I24) -> 71.569131 | M24: =AVERAGE($E24:$I24) -> 71.569131 | N24: =AVERAGE($E24:$I24) -> 71.569131 | O24: =AVERAGE($E24:$I24) -> 71.569131 | P24: =AVERAGE($E24:$I24) -> 71.569131 | Q24: =AVERAGE($E24:$I24) -> 71.569131 | ... S24: =AVERAGE($E24:$I24) -> 71.569131
B25: Capital Assets Turnover Ratio | D25: Times | E25: =E30/E68 -> 5.2728689 | F25: =F30/F68 -> 5.9767488 | G25: =G30/G68 -> 4.9666458 | H25: =H30/H68 -> 3.6773592 | I25: =I30/I68 -> 3.6911314 | J25: =I25-0.2 -> 3.4911314 | K25: =J25-0.2 -> 3.2911314 | L25: =K25-0.2 -> 3.0911314 | M25: =L25-0.2 -> 2.8911314 | N25: =M25-0.2 -> 2.6911314 | O25: =N25-0.2 -> 2.4911314 | P25: =O25-0.2 -> 2.2911314 | Q25: =P25-0.2 -> 2.0911314 | ... S25: =R25-0.2 -> 1.6911314
B27: Income Statement
B29: Income
B30: Revenue | E30: =SUM('P&L'!D10,'P&L'!D11,'P&L'!D12) -> 29101.28 | F30: =SUM('P&L'!E10,'P&L'!E11,'P&L'!E12) -> 34488.59 | G30: =SUM('P&L'!F10,'P&L'!F11,'P&L'!F12) -> 35494.73 | H30: =SUM('P&L'!G10,'P&L'!G11,'P&L'!G12) -> 33905.62 | I30: =SUM('P&L'!H10,'P&L'!H11,'P&L'!H12) -> 35583.54 | J30: =I30*(1+J12) -> 37638.61 | K30: =J30*(1+K12) -> 39925.283 | L30: =K30*(1+L12) -> 42470.656 | M30: =L30*(1+M12) -> 45305.716 | N30: =M30*(1+N12) -> 48465.943 | O30: =N30*(1+O12) -> 51992.005 | P30: =O30*(1+P12) -> 55930.575 | Q30: =P30*(1+Q12) -> 60335.298 | ... S30: =R30*(1+S12) -> 70799.59
B31: Less: Cost of Goods Sold (COGS) | E31: =-SUM('P&L'!D17,'P&L'!D18,'P&L'!D19) -> -18300.75 | F31: =-SUM('P&L'!E17,'P&L'!E18,'P&L'!E19) -> -21156.5 | G31: =-SUM('P&L'!F17,'P&L'!F18,'P&L'!F19) -> -20090.21 | H31: =-SUM('P&L'!G17,'P&L'!G18,'P&L'!G19) -> -19515.78 | I31: =-SUM('P&L'!H17,'P&L'!H18,'P&L'!H19) -> -20001.78 | J31: =-J30*J13 -> -22176.693 | K31: =-K30*K13 -> -23524.003 | L31: =-L30*L13 -> -25023.738 | M31: =-M30*M13 -> -26694.157 | N31: =-N30*N13 -> -28556.165 | O31: =-O30*O13 -> -30633.723 | P31: =-P30*P13 -> -32954.331 | Q31: =-Q30*Q13 -> -35549.597 | ... S31: =-S30*S13 -> -41715.164
B33: Gross Profit | E33: =SUM(E30:E31) -> 10800.53 | F33: =SUM(F30:F31) -> 13332.09 | G33: =SUM(G30:G31) -> 15404.52 | H33: =SUM(H30:H31) -> 14389.84 | I33: =SUM(I30:I31) -> 15581.76 | J33: =SUM(J30:J31) -> 15461.917 | K33: =SUM(K30:K31) -> 16401.281 | L33: =SUM(L30:L31) -> 17446.918 | ... S33: =SUM(S30:S31) -> 29084.426
B35: Expenses
B36: Less: Employee Benefits Expenses | E36: =-'P&L'!D20 -> -1786.67 | F36: =-'P&L'!E20 -> -2028.07 | G36: =-'P&L'!F20 -> -2326.18 | H36: =-'P&L'!G20 -> -2597.23 | I36: =-'P&L'!H20 -> -2799.59 | J36: =-J30*J14 -> -2567.0526 | K36: =-K30*K14 -> -2723.0098 | L36: =-L30*L14 -> -2896.6109 | M36: =-M30*M14 -> -3089.9695 | N36: =-N30*N14 -> -3305.5053 | O36: =-O30*O14 -> -3545.9921 | P36: =-P30*P14 -> -3814.613 | Q36: =-Q30*Q14 -> -4115.0267 | ... S36: =-S30*S14 -> -4828.719
B37: Less: Other SG&A Expenses | E37: =-'P&L'!D21 -> -4210.25 | F37: =-'P&L'!E21 -> -5044.18 | G37: =-'P&L'!F21 -> -5493.36 | H37: =-'P&L'!G21 -> -5786.4 | I37: =-'P&L'!H21 -> -6086.25 | J37: =-J30*J15 -> -5927.3351 | K37: =-K30*K15 -> -6287.4408 | L37: =-L30*L15 -> -6688.2865 | M37: =-M30*M15 -> -7134.7523 | N37: =-N30*N15 -> -7632.4254 | O37: =-O30*O15 -> -8187.7103 | P37: =-P30*P15 -> -8807.9571 | Q37: =-Q30*Q15 -> -9501.6136 | ... S37: =-S30*S15 -> -11149.532
B39: Earning Before Interest Tax Depeciation & Amortization (EBITDA) | E39: =SUM(E33:E37) -> 4803.61 | F39: =SUM(F33:F37) -> 6259.84 | G39: =SUM(G33:G37) -> 7584.98 | H39: =SUM(H33:H37) -> 6006.21 | I39: =SUM(I33:I37) -> 6695.92 | J39: =SUM(J33:J37) -> 6967.529 | K39: =SUM(K33:K37) -> 7390.83 | L39: =SUM(L33:L37) -> 7862.0204 | ... S39: =SUM(S33:S37) -> 13106.175
B40: Less: Depreciation & Amortisation Expenses | E40: =-'P&L'!D27 -> -816.36 | F40: =-'P&L'!E27 -> -858.02 | G40: =-'P&L'!F27 -> -853 | H40: =-'P&L'!G27 -> -1026.34 | I40: =-'P&L'!H27 -> -1228.85 | J40: =J139 -> -1118.6159 | K40: =K139 -> -1057.1215 | L40: =L139 -> -1015.0791 | M40: =M139 -> -992.84258 | N40: =N139 -> -991.42268 | O40: =O139 -> -1012.6443 | P40: =P139 -> -1059.3837 | Q40: =Q139 -> -1135.9285 | ... S40: =S139 -> -1406.3155
B42: Earning Before Interest Tax (EBIT) | E42: =SUM(E39:E40) -> 3987.25 | F42: =SUM(F39:F40) -> 5401.82 | G42: =SUM(G39:G40) -> 6731.98 | H42: =SUM(H39:H40) -> 4979.87 | I42: =SUM(I39:I40) -> 5467.07 | J42: =SUM(J39:J40) -> 5848.913 | K42: =SUM(K39:K40) -> 6333.7085 | L42: =SUM(L39:L40) -> 6846.9413 | ... S42: =SUM(S39:S40) -> 11699.859
B43: Less: Interest | E43: =-'P&L'!D26 -> -95.41 | F43: =-'P&L'!E26 -> -144.45 | G43: =-'P&L'!F26 -> -205.17 | H43: =-'P&L'!G26 -> -227.02 | I43: =-'P&L'!H26 -> -195.41 | J43: =J146 -> -294.08714 | K43: =K146 -> -294.08714 | L43: =L146 -> -294.08714 | M43: =M146 -> -294.08714 | N43: =N146 -> -294.08714 | O43: =O146 -> -294.08714 | P43: =P146 -> -294.08714 | Q43: =Q146 -> -294.08714 | ... S43: =S146 -> -294.08714
B44: Add: Other Income | E44: ='P&L'!D13 -> 380.01 | F44: ='P&L'!E13 -> 386.48 | G44: ='P&L'!F13 -> 687.96 | H44: ='P&L'!G13 -> 572.61 | I44: ='P&L'!H13 -> 723.8 | J44: =J30*J18 -> 608.80799 | K44: =K30*K18 -> 645.79514 | L44: =L30*L18 -> 686.96678 | M44: =M30*M18 -> 732.82414 | N44: =N30*N18 -> 783.94111 | O44: =O30*O18 -> 840.97548 | P44: =P30*P18 -> 904.68222 | Q44: =Q30*Q18 -> 975.92902 | ... S44: =S30*S18 -> 1145.1899
B46: Earning Before Tax & Exceptional Item | E46: =SUM(E42:E44) -> 4271.85 | F46: =SUM(F42:F44) -> 5643.85 | G46: =SUM(G42:G44) -> 7214.77 | H46: =SUM(H42:H44) -> 5325.46 | I46: =SUM(I42:I44) -> 5995.46 | J46: =SUM(J42:J44) -> 6163.6339 | K46: =SUM(K42:K44) -> 6685.4165 | L46: =SUM(L42:L44) -> 7239.8209 | ... S46: =SUM(S42:S44) -> 12550.962
B47: Non - Operating Income | E47: ='P&L'!D29 -> 31.57 | F47: ='P&L'!E29 -> 93.85 | G47: ='P&L'!F29 -> 133 | H47: ='P&L'!G29 -> 140.71 | I47: ='P&L'!H29 -> 165.59 | J47: =J30*J19 -> 123.12841 | K47: =K30*K19 -> 130.60888 | L47: =L30*L19 -> 138.93564 | M47: =M30*M19 -> 148.21006 | N47: =N30*N19 -> 158.54821 | O47: =O30*O19 -> 170.08314 | P47: =P30*P19 -> 182.96751 | Q47: =Q30*Q19 -> 197.37682 | ... S47: =S30*S19 -> 231.609
B48: Less: Exceptional Items | E48: =-'P&L'!D32 -> -115.7 | F48: =-'P&L'!E32 -> -48.87 | G48: =-'P&L'!F32 -> 0 | H48: =-'P&L'!G32 -> -363.1 | I48: =-'P&L'!H32 -> -157.61 | J48: =I48 -> -157.61 | K48: =J48 -> -157.61 | L48: =K48 -> -157.61 | M48: =L48 -> -157.61 | N48: =M48 -> -157.61 | O48: =N48 -> -157.61 | P48: =O48 -> -157.61 | Q48: =P48 -> -157.61 | ... S48: =R48 -> -157.61
B50: Earning Before Tax | E50: =SUM(E46:E48) -> 4187.72 | F50: =SUM(F46:F48) -> 5688.83 | G50: =SUM(G46:G48) -> 7347.77 | H50: =SUM(H46:H48) -> 5103.07 | I50: =SUM(I46:I48) -> 6003.44 | J50: =SUM(J46:J48) -> 6129.1523 | K50: =SUM(K46:K48) -> 6658.4153 | L50: =SUM(L46:L48) -> 7221.1466 | ... S50: =SUM(S46:S48) -> 12624.961
B51: Less: Taxes | E51: =-'P&L'!D38 -> -1102.91 | F51: =-'P&L'!E38 -> -1493.5 | G51: =-'P&L'!F38 -> -1790.08 | H51: =-'P&L'!G38 -> -1393.36 | I51: =-'P&L'!H38 -> -1608.75 | J51: =-J50*J20 -> -1606.4958 | K51: =-K50*K20 -> -1745.2196 | L51: =-L50*L20 -> -1892.7156 | M51: =-M50*M20 -> -2050.5526 | N51: =-N50*N20 -> -2220.3681 | O51: =-O50*O20 -> -2403.8642 | P51: =-P50*P20 -> -2602.7897 | Q51: =-Q50*Q20 -> -2818.8967 | ... S51: =-S50*S20 -> -3309.095
B53: Net Earning | E53: =SUM(E50:E51) -> 3084.81 | F53: =SUM(F50:F51) -> 4195.33 | G53: =SUM(G50:G51) -> 5557.69 | H53: =SUM(H50:H51) -> 3709.71 | I53: =SUM(I50:I51) -> 4394.69 | J53: =SUM(J50:J51) -> 4522.6565 | K53: =SUM(K50:K51) -> 4913.1958 | L53: =SUM(L50:L51) -> 5328.431 | ... S53: =SUM(S50:S51) -> 9315.8659
...

Sheet Ratios
B2: Asian Paints Ltd
B3: ASIANPAINT | 500820
B4: Ratios Analysis & Interptetation | E4: 2022 | F4: =E4+1 -> 2023 | G4: =F4+1 -> 2024 | H4: =G4+1 -> 2025 | I4: =H4+1 -> 2026 | J4: =I4+1 -> 2027 | K4: =J4+1 -> 2028 | L4: =K4+1 -> 2029 | M4: =L4+1 -> 2030 | ... S4: =R4+1 -> 2036 | V4: Interpretation
B6: Profitability Ratios
B7: Gross Margin | E7: =Model!E33/Model!E30 -> 0.37113591 | F7: =Model!F33/Model!F30 -> 0.38656524 | G7: =Model!G33/Model!G30 -> 0.43399457 | H7: =Model!H33/Model!H30 -> 0.4244087 | I7: =Model!I33/Model!I30 -> 0.43789235 | J7: =Model!J33/Model!J30 -> 0.41079935 | K7: =Model!K33/Model!K30 -> 0.41079935 | L7: =Model!L33/Model!L30 -> 0.41079935 | ... S7: =Model!S33/Model!S30 -> 0.41079935 | V7: Gross margin increased from 37.1% to 43.8% during the historical period, indicating improved cost efficiency, pricing power, and product mix. However, the margin is projected to stabilize at 41.1% in the forecast period, reflecting a conservative assumption and normalization of margins.
B8: EBITDA Margin | E8: =Model!E39/Model!E30 -> 0.16506525 | F8: =Model!F39/Model!F30 -> 0.18150467 | G8: =Model!G39/Model!G30 -> 0.21369313 | H8: =Model!H39/Model!H30 -> 0.17714497 | I8: =Model!I39/Model!I30 -> 0.18817464 | J8: =Model!J39/Model!J30 -> 0.18511653 | K8: =Model!K39/Model!K30 -> 0.18511653 | L8: =Model!L39/Model!L30 -> 0.18511653 | ... S8: =Model!S39/Model!S30 -> 0.18511653 | V8: EBITDA margin improved from 16.5% to 21.4% during the historical period, reflecting stronger operating efficiency and better cost management. It is then projected to remain broadly stable at around 18.5%, indicating a conservative assumption of normalized operating profitability and consistent cost control.
B9: Operating Margin | E9: =Model!E42/Model!E30 -> 0.13701287 | F9: =Model!F42/Model!F30 -> 0.15662629 | G9: =Model!G42/Model!G30 -> 0.18966139 | H9: =Model!H42/Model!H30 -> 0.14687447 | I9: =Model!I42/Model!I30 -> 0.15364042 | J9: =Model!J42/Model!J30 -> 0.15539663 | K9: =Model!K42/Model!K30 -> 0.15863904 | L9: =Model!L42/Model!L30 -> 0.16121581 | ... S9: =Model!S42/Model!S30 -> 0.1652532 | V9: Operating margin improved from 13.7% to 19.0%, indicating better operational efficiency. It is projected to gradually increase to 16.4%, reflecting steady improvement in profitability and cost management.
B10: Pretax Margin | E10: =Model!E50/Model!E30 -> 0.14390157 | F10: =Model!F50/Model!F30 -> 0.16494818 | G10: =Model!G50/Model!G30 -> 0.20701017 | H10: =Model!H50/Model!H30 -> 0.15050809 | I10: =Model!I50/Model!I30 -> 0.16871396 | J10: =Model!J50/Model!J30 -> 0.16284215 | K10: =Model!K50/Model!K30 -> 0.1667719 | L10: =Model!L50/Model!L30 -> 0.17002673 | ... S10: =Model!S50/Model!S30 -> 0.17831969 | V10: Pretax margin improved from 14.4% to 20.7%, indicating stronger profitability. It is projected to gradually increase to 17.5%, reflecting stable earnings and improved cost efficiency.
B11: Effective Tax rate | E11: =-Model!E51/Model!E50 -> 0.26336766 | F11: =-Model!F51/Model!F50 -> 0.26253201 | G11: =-Model!G51/Model!G50 -> 0.24362221 | H11: =-Model!H51/Model!H50 -> 0.27304348 | I11: =-Model!I51/Model!I50 -> 0.26797136 | J11: =-Model!J51/Model!J50 -> 0.26210735 | K11: =-Model!K51/Model!K50 -> 0.26210735 | L11: =-Model!L51/Model!L50 -> 0.26210735 | ... S11: =-Model!S51/Model!S50 -> 0.26210735 | V11: Effective tax rate remained relatively stable between 24.4% and 27.3% and is projected at around 26.2%, indicating a consistent tax burden and stable tax assumptions.
B12: Net Margin | E12: =Model!E53/Model!E30 -> 0.10600255 | F12: =Model!F53/Model!F30 -> 0.121644 | G12: =Model!G53/Model!G30 -> 0.15657789 | H12: =Model!H53/Model!H30 -> 0.10941283 | I12: =Model!I53/Model!I30 -> 0.12350345 | J12: =Model!J53/Model!J30 -> 0.12016003 | K12: =Model!K53/Model!K30 -> 0.12305976 | L12: =Model!L53/Model!L30 -> 0.12546147 | ... S12: =Model!S53/Model!S30 -> 0.13158079 | V12: Net margin improved from 10.6% to 15.7%, reflecting stronger profitability. It is projected to gradually improve to 12.9%, indicating stable earnings growth and cost control.
B14: DuPont/Earning Power
B15: Asset Turnover | F15: =Model!F30/AVERAGE(Model!E73:F73) -> 1.4139753 | G15: =Model!G30/AVERAGE(Model!F73:G73) -> 1.2739913 | H15: =Model!H30/AVERAGE(Model!G73:H73) -> 1.1246492 | I15: =Model!I30/AVERAGE(Model!H73:I73) -> 1.0964662 | J15: =Model!J30/AVERAGE(Model!I73:J73) -> 1.0533785 | K15: =Model!K30/AVERAGE(Model!J73:K73) -> 1.0479957 | L15: =Model!L30/AVERAGE(Model!K73:L73) -> 1.0477107 | M15: =Model!M30/AVERAGE(Model!L73:M73) -> 1.0489991 | ... S15: =Model!S30/AVERAGE(Model!R73:S73) -> 1.0938836 | V15: Asset turnover declined from 5.72 to 3.93 and is projected to gradually fall to 2.88, indicating lower asset utilization and increasing asset intensity over time.
B17: Liquidity Ratio
B18: Quick ratio | E18: =SUM(Model!E61:E63)/(SUM(Model!E77:E78)) -> 0.71497747 | F18: =SUM(Model!F61:F63)/(SUM(Model!F77:F78)) -> 0.81007771 | G18: =SUM(Model!G61:G63)/(SUM(Model!G77:G78)) -> 0.83258526 | H18: =SUM(Model!H61:H63)/(SUM(Model!H77:H78)) -> 0.70561775 | I18: =SUM(Model!I61:I63)/(SUM(Model!I77:I78)) -> 0.71382248 | J18: =SUM(Model!J61:J63)/(SUM(Model!J77:J78)) -> 0.88589265 | K18: =SUM(Model!K61:K63)/(SUM(Model!K77:K78)) -> 1.126297 | L18: =SUM(Model!L61:L63)/(SUM(Model!L77:L78)) -> 1.3461583 | ... S18: =SUM(Model!S61:S63)/(SUM(Model!S77:S78)) -> 2.1882939 | V18: Quick Ratio: Improved from 0.68 to 0.80, then declined to 0.66, before being projected to rise steadily to 1.63, indicating strengthening short-term liquidity.
B19: Current ratio | E19: {=SUM(Model!E61:E65/SUM(Model!E77:E78))} -> 1.7263461 | F19: {=SUM(Model!F61:F65/SUM(Model!F77:F78))} -> 1.8095192 | G19: {=SUM(Model!G61:G65/SUM(Model!G77:G78))} -> 1.7675081 | H19: {=SUM(Model!H61:H65/SUM(Model!H77:H78))} -> 1.7414382 | I19: {=SUM(Model!I61:I65/SUM(Model!I77:I78))} -> 1.5563918 | J19: {=SUM(Model!J61:J65/SUM(Model!J77:J78))} -> 1.8192837 | K19: {=SUM(Model!K61:K65/SUM(Model!K77:K78))} -> 2.0799798 | L19: {=SUM(Model!L61:L65/SUM(Model!L77:L78))} -> 2.3209966 | ... S19: {=SUM(Model!S61:S65/SUM(Model!S77:S78))} -> 3.3290533 | V19: Current Ratio: Remained around 1.5–1.8 historically and is projected to increase to 2.71, indicating a stronger ability to meet short-term obligations.
B20: Cash Cycle (Days) | E20: =Model!E22+Model!E23-Model!E24 -> 88.250568 | F20: =Model!F22+Model!F23-Model!F24 -> 93.525008 | G20: =Model!G22+Model!G23-Model!G24 -> 88.302303 | H20: =Model!H22+Model!H23-Model!H24 -> 100.2318 | I20: =Model!I22+Model!I23-Model!I24 -> 80.140933 | J20: =Model!J22+Model!J23-Model!J24 -> 90.090122 | K20: =Model!K22+Model!K23-Model!K24 -> 90.090122 | L20: =Model!L22+Model!L23-Model!L24 -> 90.090122 | ... S20: =Model!S22+Model!S23-Model!S24 -> 90.090122 | V20: Cash Cycle: Fluctuated between 80 and 100 days historically and is projected to remain stable at 90 days, indicating consistent working-capital management.
B22: Leverage
B23: Asset/Equity | E23: =Model!E73/Model!E89 -> 1.6641458 | F23: =Model!F73/Model!F89 -> 1.6131584 | G23: =Model!G73/Model!G89 -> 1.5978007 | H23: =Model!H73/Model!H89 -> 1.5655499 | I23: =Model!I73/Model!I89 -> 1.6159064 | J23: =Model!J73/Model!J89 -> 1.5862681 | K23: =Model!K73/Model!K89 -> 1.5487494 | L23: =Model!L73/Model!L89 -> 1.5147044 | ... S23: =Model!S73/Model!S89 -> 1.3529137 | V23: Asset/Equity: Declined from 1.66 to 1.57 and is projected to gradually decrease to 1.46, indicating lower financial leverage and a stronger equity base.
B24: Debt/Equity | E24: =Model!E81/Model!E89 -> 0.11489506 | F24: =Model!F81/Model!F89 -> 0.12084744 | G24: =Model!G81/Model!G89 -> 0.13211984 | H24: =Model!H81/Model!H89 -> 0.11805734 | I24: =Model!I81/Model!I89 -> 0.18383892 | J24: =Model!J81/Model!J89 -> 0.1687692 | K24: =Model!K81/Model!K89 -> 0.15496906 | L24: =Model!L81/Model!L89 -> 0.14234584 | ... S24: =Model!S81/Model!S89 -> 0.079326308 | V24: Debt/Equity: Increased from 0.11 to 0.18 before declining to 0.12, indicating relatively low debt levels and improving financial stability.
B26: Operating
B27: A/R Turnover | F27: =Model!F30/AVERAGE(Model!E63:F63) -> 8.1026178 | G27: =Model!G30/AVERAGE(Model!F63:G63) -> 7.4490983 | H27: =Model!H30/AVERAGE(Model!G63:H63) -> 7.3602346 | I27: =Model!I30/AVERAGE(Model!H63:I63) -> 8.0968107 | J27: =Model!J30/AVERAGE(Model!I63:J63) -> 7.9880652 | K27: =Model!K30/AVERAGE(Model!J63:K63) -> 7.8175808 | L27: =Model!L30/AVERAGE(Model!K63:L63) -> 7.828294 | M27: =Model!M30/AVERAGE(Model!L63:M63) -> 7.8389762 | ... S27: =Model!S30/AVERAGE(Model!R63:S63) -> 7.9024235 | V27: A/R Turnover: Remained relatively stable around 7.3–8.0x, indicating consistent collection efficiency.
B28: Avg. A/R Days | F28: =Model!F22 -> 49.096677 | G28: =Model!G22 -> 50.293465 | H28: =Model!H22 -> 46.53097 | I28: =Model!I22 -> 45.822124 | J28: =Model!J22 -> 48.0661 | K28: =Model!K22 -> 48.0661 | L28: =Model!L22 -> 48.0661 | M28: =Model!M22 -> 48.0661 | ... S28: =Model!S22 -> 48.0661 | V28: Avg. A/R Days: Stayed within 46–50 days and is projected at 48 days, reflecting stable receivables management.
B29: Inventory Turnover | F29: =-Model!F31/AVERAGE(Model!E64:F64) -> 3.4223795 | G29: =-Model!G31/AVERAGE(Model!F64:G64) -> 3.3113775 | H29: =-Model!H31/AVERAGE(Model!G64:H64) -> 3.0872853 | I29: =-Model!I31/AVERAGE(Model!H64:I64) -> 3.2097961 | J29: =-Model!J31/AVERAGE(Model!I64:J64) -> 3.5074748 | K29: =-Model!K31/AVERAGE(Model!J64:K64) -> 3.3079513 | L29: =-Model!L31/AVERAGE(Model!K64:L64) -> 3.3124846 | M29: =-Model!M31/AVERAGE(Model!L64:M64) -> 3.3170046 | ... S29: =-Model!S31/AVERAGE(Model!R64:S64) -> 3.3438519 | V29: Inventory Turnover: Fluctuated between 2.9–3.5x and is projected at 3.2x, indicating stable inventory management
B30: Avg. Inventory Days | F30: =Model!F23 -> 107.14833 | G30: =Model!G23 -> 107.61683 | H30: =Model!H23 -> 125.66926 | I30: =Model!I23 -> 104.81301 | J30: =Model!J23 -> 113.59315 | K30: =Model!K23 -> 113.59315 | L30: =Model!L23 -> 113.59315 | M30: =Model!M23 -> 113.59315 | ... S30: =Model!S23 -> 113.59315 | V30: Avg. Inventory Days: Improved from 123 to 105 days, then stabilized at 114 days, indicating consistent inventory holding.
B31: A/P Turnover | F31: =-Model!F31/AVERAGE(Model!E77:F77) -> 5.4249244 | G31: =-Model!G31/AVERAGE(Model!F77:G77) -> 5.3812246 | H31: =-Model!H31/AVERAGE(Model!G77:H77) -> 5.0826712 | I31: =-Model!I31/AVERAGE(Model!H77:I77) -> 5.1878294 | J31: =-Model!J31/AVERAGE(Model!I77:J77) -> 5.4014128 | K31: =-Model!K31/AVERAGE(Model!J77:K77) -> 5.2503169 | L31: =-Model!L31/AVERAGE(Model!K77:L77) -> 5.257512 | M31: =-Model!M31/AVERAGE(Model!L77:M77) -> 5.2646862 | ... S31: =-Model!S31/AVERAGE(Model!R77:S77) -> 5.3072976 | V31: A/P Turnover: Ranged between 4.4–5.8x and is projected at 5.1x, reflecting stable payment practices.
B32: Avg. A/P Days | F32: =Model!F24 -> 62.719996 | G32: =Model!G24 -> 69.607988 | H32: =Model!H24 -> 71.968428 | I32: =Model!I24 -> 70.494206 | J32: =Model!J24 -> 71.569131 | K32: =Model!K24 -> 71.569131 | L32: =Model!L24 -> 71.569131 | M32: =Model!M24 -> 71.569131 | ... S32: =Model!S24 -> 71.569131 | V32: Avg. A/P Days: Improved from 83 to 70 days and is projected at 72 days, indicating consistent supplier payment management
B33: Fixed Asset Turnover | F33: =Model!F30/AVERAGE(Model!E68:F68) -> 6.1098417 | G33: =Model!G30/AVERAGE(Model!F68:G68) -> 5.4957823 | H33: =Model!H30/AVERAGE(Model!G68:H68) -> 4.1432395 | I33: =Model!I30/AVERAGE(Model!H68:I68) -> 3.7733641 | J33: =Model!J30/AVERAGE(Model!I68:J68) -> 4.0146569 | K33: =Model!K30/AVERAGE(Model!J68:K68) -> 4.4713385 | L33: =Model!L30/AVERAGE(Model!K68:L68) -> 4.9086665 | M33: =Model!M30/AVERAGE(Model!L68:M68) -> 5.2987644 | ... S33: =Model!S30/AVERAGE(Model!R68:S68) -> 5.4244142 | V33: Fixed Asset Turnover: Declined from 2.5x to 1.6x, but is projected to recover to 2.3x, indicating improving utilization of fixed assets.
B34: ROIC | F34: =Model!E42*(1-Model!E20)/AVERAGE((Model!E89+Model!E81-Model!E61),(Model!F89+Model!F81-Model!F61)) -> 0.18255295 | G34: =Model!F42*(1-Model!F20)/AVERAGE((Model!F89+Model!F81-Model!F61),(Model!G89+Model!G81-Model!G61)) -> 0.21091515 | H34: =Model!G42*(1-Model!G20)/AVERAGE((Model!G89+Model!G81-Model!G61),(Model!H89+Model!H81-Model!H61)) -> 0.24469703 | I34: =Model!H42*(1-Model!H20)/AVERAGE((Model!H89+Model!H81-Model!H61),(Model!I89+Model!I81-Model!I61)) -> 0.15783522 | J34: =Model!I42*(1-Model!I20)/AVERAGE((Model!I89+Model!I81-Model!I61),(Model!J89+Model!J81-Model!J61)) -> 0.1604432 | K34: =Model!J42*(1-Model!J20)/AVERAGE((Model!J89+Model!J81-Model!J61),(Model!K89+Model!K81-Model!K61)) -> 0.17054237 | L34: =Model!K42*(1-Model!K20)/AVERAGE((Model!K89+Model!K81-Model!K61),(Model!L89+Model!L81-Model!L61)) -> 0.18319348 | M34: =Model!L42*(1-Model!L20)/AVERAGE((Model!L89+Model!L81-Model!L61),(Model!M89+Model!M81-Model!M61)) -> 0.19471916 | ... S34: =Model!R42*(1-Model!R20)/AVERAGE((Model!R89+Model!R81-Model!R61),(Model!S89+Model!S81-Model!S61)) -> 0.22667847 | V34: ROIC: Improved to 26% historically and is projected to stabilize around 18%, indicating healthy returns on invested capital.

Sheet WACC
B2: Asian Paints Ltd
B3: ASIANPAINT | 500820
B4: Financial Statement & DCF Analysis
B6: Comparable Company Beta
B8: Company Name | D8: Equity Value | E8: Total Debt | F8: Debt/Equity | G8: Debt/Capital | H8: Tax Rate | I8: Levered Beta | J8: Unlevered Beta
B10: Asian Paints | D10: ='Company Valuation'!F9 -> 264590 | E10: ='Company Valuation'!G9 -> 3928.93 | F10: =E10/D10 -> 0.014849125 | G10: =E10/(D10+E10) -> 0.014631855 | H10: ='Company Data'!R9 -> 0.27 | I10: 0.12 | J10: =I10/(1+F10*(1-H10)) -> 0.11871317
B11: Berger Paints | D11: ='Company Valuation'!F10 -> 60613.92 | E11: ='Company Valuation'!G10 -> 635.13 | F11: =E11/D11 -> 0.010478286 | G11: =E11/(D11+E11) -> 0.01036963 | H11: ='Company Data'!R10 -> 0.24 | I11: 0.24 | J11: =I11/(1+F11*(1-H11)) -> 0.23810386
B12: Kansai Nerolac | D12: ='Company Valuation'!F11 -> 16213.34 | E12: ='Company Valuation'!G11 -> 302.73 | F12: =E12/D12 -> 0.018671662 | G12: =E12/(D12+E12) -> 0.018329421 | H12: ='Company Data'!R11 -> 0.31 | I12: 0.3 | J12: =I12/(1+F12*(1-H12)) -> 0.29618413
B13: JSW Dulux | D13: ='Company Valuation'!F12 -> 13529.69 | E13: ='Company Valuation'!G12 -> 79.1 | F13: =E13/D13 -> 0.0058464015 | G13: =E13/(D13+E13) -> 0.0058124198 | H13: ='Company Data'!R12 -> 0.17 | I13: 0.43 | J13: =I13/(1+F13*(1-H13)) -> 0.4279235
B14: Indigo Paints | D14: ='Company Valuation'!F13 -> 5272.62 | E14: ='Company Valuation'!G13 -> 18.37 | F14: =E14/D14 -> 0.0034840364 | G14: =E14/(D14+E14) -> 0.00347194 | H14: ='Company Data'!R13 -> 0.26 | I14: 0.51 | J14: =I14/(1+F14*(1-H14)) -> 0.50868851
B15: Sirca Paints | D15: ='Company Valuation'!F14 -> 2284.76 | E15: ='Company Valuation'!G14 -> 32.32 | F15: =E15/D15 -> 0.014145906 | G15: =E15/(D15+E15) -> 0.01394859 | H15: ='Company Data'!R14 -> 0.25 | I15: 0.7 | J15: =I15/(1+F15*(1-H15)) -> 0.69265136
B16: Shalimar Paints | D16: ='Company Valuation'!F15 -> 579.38 | E16: ='Company Valuation'!G15 -> 164.76 | F16: =E16/D16 -> 0.28437295 | G16: =E16/(D16+E16) -> 0.22140995 | H16: ='Company Data'!R15 -> -0.01 | I16: 0.28 | J16: =I16/(1+F16*(1-H16)) -> 0.2175236
B18: Average | F18: =AVERAGE(F10:F16) -> 0.050264052 | G18: =AVERAGE(G10:G16) -> 0.041139115 | H18: =AVERAGE(H10:H16) -> 0.21285714 | I18: =AVERAGE(I10:I16) -> 0.36857143 | J18: =AVERAGE(J10:J16) -> 0.35711259
B19: Median | F19: =MEDIAN(F10:F16) -> 0.014145906 | G19: =MEDIAN(G10:G16) -> 0.01394859 | H19: =MEDIAN(H10:H16) -> 0.25 | I19: =MEDIAN(I10:I16) -> 0.3 | J19: =MEDIAN(J10:J16) -> 0.29618413
B21: =B10 -> Asian Paints | D21: =D10 -> 264590 | E21: =E10 -> 3928.93 | F21: =F10 -> 0.014849125 | G21: =G10 -> 0.014631855 | H21: =H10 -> 0.27 | I21: =I10 -> 0.12 | J21: =J10 -> 0.11871317
B23: WACC Calculation
B25: Target Capital Structure
B27: Proportion of Debt | D27: =G18 -> 0.041139115
B28: Proportion of Equity | D28: =1-D27 -> 0.95886088
B30: Current Capital Structure
B32: Market Cap | D32: =D21 -> 264590
B33: Total Debt | D33: =E21 -> 3928.93
B34: Debt/Equity | D34: =D33/D32 -> 0.014849125
B36: Cost of Debt
B38: Pre-Tax Cost of Debt | D38: 0.075
B39: Tax Rate | D39: =Model!J20 -> 0.26210735
B40: After Tax Cost of Debt | D40: =D38*(1-D39) -> 0.055341949
B42: Cost of Equity
B44: Risk Free Rate (Rf) | D44: 0.0676
B45: Equity Market Return | D45: ='Index Data'!F10 -> 0.10740432
B46: Equity Risk Premium (ERP) | D46: =D45-D44 -> 0.039804324
B47: Levered Market Beta | D47: =J19*(1+D34*(1-D39)) -> 0.29942943
B48: Cost of Equity | D48: =D44+(D46*D47) -> 0.079518586
B50: WACC | D50: =(D40*D27)+(D48*D28) -> 0.078523981

Sheet Beta
B2: Asian Paints Ltd
B3: ASIANPAINT | 500820
B4: Financial Statement & DCF Analysis
C6: Index | D6: % Change | E6: Stock | F6: % Change | H6: 52W High | I6: =MAX(E47:E58) -> 2873.4 | K6: Another Marthod Of Calculating Beta
B7: Date | C7: Close Price | D7: Monthly | E7: Close Price | F7: Monthly | H7: 52W Low | I7: =MIN(E47:E58) -> 2164.5
B9: 44743 | C9: 57570.25 | E9: 3332.35 | H9: Beta | I9: =SLOPE(D10:D58,F10:F58) -> 0.2945679
B10: 44774 | C10: 59537.07 | D10: =C10/C9-1 -> 0.034163826 | E10: 3391.6 | F10: =E10/E9-1 -> 0.017780245
B11: 44805 | C11: 57426.92 | D11: =C11/C10-1 -> -0.035442624 | E11: 3342.15 | F11: =E11/E10-1 -> -0.014580139
B12: 44835 | C12: 60746.59 | D12: =C12/C11-1 -> 0.057806861 | E12: 3106.8 | F12: =E12/E11-1 -> -0.070418742 | H12: SUMMARY OUTPUT
B13: 44866 | C13: 63099.65 | D13: =C13/C12-1 -> 0.038735672 | E13: 3182.3 | F13: =E13/E12-1 -> 0.024301532
B14: 44896 | C14: 60840.74 | D14: =C14/C13-1 -> -0.035799089 | E14: 3091.8 | F14: =E14/E13-1 -> -0.028438551 | H14: Regression Statistics
B15: 44927 | C15: 59549.9 | D15: =C15/C14-1 -> -0.021216704 | E15: 2726.6 | F15: =E15/E14-1 -> -0.1181189 | H15: Multiple R | I15: 0.54727406
B16: 44958 | C16: 58962.12 | D16: =C16/C15-1 -> -0.0098703776 | E16: 2829.5 | F16: =E16/E15-1 -> 0.037739309 | H16: R Square | I16: 0.29950889
B17: 44986 | C17: 58991.52 | D17: =C17/C16-1 -> 0.00049862522 | E17: 2761.65 | F17: =E17/E16-1 -> -0.023979502 | H17: Adjusted R Square | I17: 0.28460483
B18: 45017 | C18: 61112.44 | D18: =C18/C17-1 -> 0.035952964 | E18: 2901.3 | F18: =E18/E17-1 -> 0.050567595 | H18: Standard Error | I18: 0.031178675
B19: 45047 | C19: 62622.24 | D19: =C19/C18-1 -> 0.024705281 | E19: 3198.2 | F19: =E19/E18-1 -> 0.10233344 | H19: Observations | I19: 49
B20: 45078 | C20: 64718.56 | D20: =C20/C19-1 -> 0.033475647 | E20: 3361.7 | F20: =E20/E19-1 -> 0.051122506
B21: 45108 | C21: 66527.67 | D21: =C21/C20-1 -> 0.027953496 | E21: 3374.95 | F21: =E21/E20-1 -> 0.0039414582 | H21: ANOVA
B22: 45139 | C22: 64831.41 | D22: =C22/C21-1 -> -0.02549706 | E22: 3250.65 | F22: =E22/E21-1 -> -0.036830175 | I22: df | J22: SS | K22: MS | L22: F | M22: Significance F
B23: 45170 | C23: 65828.41 | D23: =C23/C22-1 -> 0.015378348 | E23: 3161.35 | F23: =E23/E22-1 -> -0.027471429 | H23: Regression | I23: 1 | J23: 0.019535309 | K23: 0.019535309 | L23: 20.095784 | M23: 4.7159622e-05
B24: 45200 | C24: 63874.93 | D24: =C24/C23-1 -> -0.029675333 | E24: 2996.35 | F24: =E24/E23-1 -> -0.052192892 | H24: Residual | I24: 47 | J24: 0.045689161 | K24: 0.0009721098
B25: 45231 | C25: 66988.44 | D25: =C25/C24-1 -> 0.04874385 | E25: 3120 | F25: =E25/E24-1 -> 0.041266875 | H25: Total | I25: 48 | J25: 0.06522447
B26: 45261 | C26: 72240.26 | D26: =C26/C25-1 -> 0.0783989 | E26: 3402.1 | F26: =E26/E25-1 -> 0.090416667
B27: 45292 | C27: 71752.11 | D27: =C27/C26-1 -> -0.0067573123 | E27: 2958 | F27: =E27/E26-1 -> -0.13053702 | I27: Coefficients | J27: Standard Error | K27: t Stat | L27: P-value | M27: Lower 95% | N27: Upper 95% | O27: Lower 95.0% | P27: Upper 95.0%
B28: 45323 | C28: 72500.3 | D28: =C28/C27-1 -> 0.010427429 | E28: 2825.4 | F28: =E28/E27-1 -> -0.044827586 | H28: Intercept | I28: 0.0075488525 | J28: 0.0044556568 | K28: 1.6942177 | L28: 0.096841602 | M28: -0.0014147729 | N28: 0.016512478 | O28: -0.0014147729 | P28: 0.016512478
B29: 45352 | C29: 73651.35 | D29: =C29/C28-1 -> 0.015876486 | E29: 2846 | F29: =E29/E28-1 -> 0.007291003 | H29: X Variable 1 | I29: 0.2945679 | J29: 0.065710223 | K29: 4.4828322 | L29: 4.7159622e-05 | M29: 0.16237598 | N29: 0.42675982 | O29: 0.16237598 | P29: 0.42675982
B30: 45383 | C30: 74482.78 | D30: =C30/C29-1 -> 0.011288727 | E30: 2877.05 | F30: =E30/E29-1 -> 0.010910049
B31: 45413 | C31: 73961.31 | D31: =C31/C30-1 -> -0.0070012156 | E31: 2877.7 | F31: =E31/E30-1 -> 0.00022592586
B32: 45444 | C32: 79032.73 | D32: =C32/C31-1 -> 0.068568553 | E32: 2917.3 | F32: =E32/E31-1 -> 0.01376099
B33: 45474 | C33: 81741.34 | D33: =C33/C32-1 -> 0.034272004 | E33: 3082.3 | F33: =E33/E32-1 -> 0.056559147
B34: 45505 | C34: 82365.77 | D34: =C34/C33-1 -> 0.0076390967 | E34: 3126.8 | F34: =E34/E33-1 -> 0.014437271
B35: 45536 | C35: 84299.78 | D35: =C35/C34-1 -> 0.023480749 | E35: 3328.4 | F35: =E35/E34-1 -> 0.064474862
B36: 45566 | C36: 79389.06 | D36: =C36/C35-1 -> -0.058253058 | E36: 2938.1 | F36: =E36/E35-1 -> -0.11726355
B37: 45597 | C37: 79802.79 | D37: =C37/C36-1 -> 0.0052114233 | E37: 2479.95 | F37: =E37/E36-1 -> -0.15593411
B38: 45627 | C38: 78139.01 | D38: =C38/C37-1 -> -0.020848645 | E38: 2282.05 | F38: =E38/E37-1 -> -0.079799996
B39: 45658 | C39: 77500.57 | D39: =C39/C38-1 -> -0.0081705668 | E39: 2301.05 | F39: =E39/E38-1 -> 0.0083258474
B40: 45689 | C40: 73198.1 | D40: =C40/C39-1 -> -0.055515334 | E40: 2179.95 | F40: =E40/E39-1 -> -0.052628148
B41: 45717 | C41: 77414.92 | D41: =C41/C40-1 -> 0.057608326 | E41: 2337.7 | F41: =E41/E40-1 -> 0.072364045
... B58: 46235 | C58: 78499.17 | D58: =C58/C57-1 -> 0.005179997 | E58: 2721 | F58: =E58/E57-1 -> -0.010005458

Sheet Company Valuation
B2: Asian Paints Ltd
B3: ASIANPAINT | 500820
B4: Financial Statement & DCF Analysis
D6: Market Data | K6: Financial Data | O6: Valuations
B7: Company Name | C7: All No.s In Cr. | D7: Price (Rs) | E7: Shares (MM.) | F7: Market Cap. | G7: Debt | H7: Cash & Equivalent | I7: EV | K7: Sales | L7: EBITDA | M7: Earning | O7: EV/Sales | P7: EV/EBITDA | Q7: P/E
B9: Asian Paints | D9: ='Company Data'!D9 -> 2640 | E9: =F9/D9 -> 100.22348 | F9: ='Company Data'!E9 -> 264590 | G9: ='Company Data'!F9 -> 3928.93 | H9: ='Company Data'!N9 -> 3357.42 | I9: ='Company Data'!G9 -> 267445.25 | K9: ='Company Data'!H9 -> 37186.93 | L9: 6700 | M9: ='Company Data'!L9 -> 4877.01 | O9: ='Company Valuation'!I9/'Company Valuation'!K9 -> 7.1919153 | P9: ='Company Data'!J9 -> 39.917201 | Q9: ='Company Data'!K9 -> 54.25
B10: Berger Paints | D10: ='Company Data'!D10 -> 524.4 | E10: =F10/D10 -> 115.58719 | F10: ='Company Data'!E10 -> 60613.92 | G10: ='Company Data'!F10 -> 635.13 | H10: ='Company Data'!N10 -> 253.95 | I10: ='Company Data'!G10 -> 60943.74 | K10: ='Company Data'!H10 -> 11880.25 | L10: 1833 | M10: ='Company Data'!L10 -> 1131.43 | O10: ='Company Valuation'!I10/'Company Valuation'!K10 -> 5.1298365 | P10: ='Company Data'!J10 -> 33.248085 | Q10: ='Company Data'!K10 -> 53.57
B11: Kansai Nerolac | D11: ='Company Data'!D11 -> 205.85 | E11: =F11/D11 -> 78.762886 | F11: ='Company Data'!E11 -> 16213.34 | G11: ='Company Data'!F11 -> 302.73 | H11: ='Company Data'!N11 -> 29.6 | I11: ='Company Data'!G11 -> 16290.29 | K11: ='Company Data'!H11 -> 8051.91 | L11: 975 | M11: ='Company Data'!L11 -> 579.07 | O11: ='Company Valuation'!I11/'Company Valuation'!K11 -> 2.0231585 | P11: ='Company Data'!J11 -> 16.70799 | Q11: ='Company Data'!K11 -> 28
B12: JSW Dulux | D12: ='Company Data'!D12 -> 3118.8 | E12: =F12/D12 -> 4.3381076 | F12: ='Company Data'!E12 -> 13529.69 | G12: ='Company Data'!F12 -> 79.1 | H12: ='Company Data'!N12 -> 248.2 | I12: ='Company Data'!G12 -> 13285.09 | K12: ='Company Data'!H12 -> 3599.2 | L12: 509 | M12: ='Company Data'!L12 -> 361.15 | O12: ='Company Valuation'!I12/'Company Valuation'!K12 -> 3.691123 | P12: ='Company Data'!J12 -> 26.100373 | Q12: ='Company Data'!K12 -> 37.46
B13: Indigo Paints | D13: ='Company Data'!D13 -> 1151.8 | E13: =F13/D13 -> 4.5777218 | F13: ='Company Data'!E13 -> 5272.62 | G13: ='Company Data'!F13 -> 18.37 | H13: ='Company Data'!N13 -> 37.09 | I13: ='Company Data'!G13 -> 5262.44 | K13: ='Company Data'!H13 -> 1330.12 | L13: 247 | M13: ='Company Data'!L13 -> 149.75 | O13: ='Company Valuation'!I13/'Company Valuation'!K13 -> 3.9563648 | P13: ='Company Data'!J13 -> 21.305425 | Q13: ='Company Data'!K13 -> 35.21
B14: Sirca Paints | D14: ='Company Data'!D14 -> 451.2 | E14: =F14/D14 -> 5.0637411 | F14: ='Company Data'!E14 -> 2284.76 | G14: ='Company Data'!F14 -> 32.32 | H14: ='Company Data'!N14 -> 43.24 | I14: ='Company Data'!G14 -> 2259.1 | K14: ='Company Data'!H14 -> 508.26 | L14: 99 | M14: ='Company Data'!L14 -> 67.05 | O14: ='Company Valuation'!I14/'Company Valuation'!K14 -> 4.4447724 | P14: ='Company Data'!J14 -> 22.819192 | Q14: ='Company Data'!K14 -> 34.08
B15: Shalimar Paints | D15: ='Company Data'!D15 -> 80.89 | E15: =F15/D15 -> 7.1625664 | F15: ='Company Data'!E15 -> 579.38 | G15: ='Company Data'!F15 -> 164.76 | H15: 0 | I15: ='Company Data'!G15 -> 697.05 | K15: ='Company Data'!H15 -> 575.63 | L15: -22 | M15: ='Company Data'!L15 -> -60.35 | O15: ='Company Valuation'!I15/'Company Valuation'!K15 -> 1.2109341 | P15: ='Company Data'!J15 -> -31.684091 | Q15: 0
B17: Average | O17: =AVERAGE(O9:O15) -> 3.9497292 | P17: =AVERAGE(P9:P15) -> 18.344882 | Q17: =AVERAGE(Q9:Q15) -> 34.652857
B18: Median | O18: =MEDIAN(O9:O15) -> 3.9563648 | P18: =MEDIAN(P9:P15) -> 22.819192 | Q18: =MEDIAN(Q9:Q15) -> 35.21
B20: =B9 -> Asian Paints | D20: =D9 -> 2640 | E20: =E9 -> 100.22348 | F20: =F9 -> 264590 | G20: =G9 -> 3928.93 | H20: =H9 -> 3357.42 | I20: =I9 -> 267445.25 | K20: =K9 -> 37186.93 | L20: =L9 -> 6700 | M20: =M9 -> 4877.01 | O20: =O9 -> 7.1919153 | P20: =P9 -> 39.917201 | Q20: =Q9 -> 54.25
B22: Metric | D22: Comps | E22: EV | F22: Net Debt | G22: Equity Value | H22: Shares | I22: Share Price
B24: EV/Sales | D24: =O17 -> 3.9497292 | E24: =D24*K20 -> 146878.3 | F24: =$G$20-$H$20 -> 571.51 | G24: =E24+F24 -> 147449.81 | H24: =E20 -> 100.22348 | I24: =G24/H24 -> 1471.2102
B25: EV/EBITDA | D25: =P18 -> 22.819192 | E25: =D25*L20 -> 152888.59 | F25: =F24 -> 571.51 | G25: =E25+F25 -> 153460.1 | H25: =H24 -> 100.22348 | I25: =G25/H25 -> 1531.179
B26: P/E | D26: =Q17 -> 34.652857 | E26: =G26+F26 -> 169573.84 | F26: =F25 -> 571.51 | G26: =D26*M20 -> 169002.33 | H26: =H25 -> 100.22348 | I26: =G26/H26 -> 1686.2548

Sheet Scenario
B2: Asian Paints Ltd
B3: ASIANPAINT | 500820
B4: Financial Statement & DCF Analysis
B6: Scenarios | D6: Growth (%) | F6: =Model!J4 -> 2027 | G6: =Model!K4 -> 2028 | H6: =Model!L4 -> 2029 | I6: =Model!M4 -> 2030 | J6: =Model!N4 -> 2031 | K6: =Model!O4 -> 2032 | L6: =Model!P4 -> 2033 | M6: =Model!Q4 -> 2034 | ... O6: =Model!S4 -> 2036
B8: Base Case | D8: =AVERAGE(Model!F12:I12) -> 0.054753391 | F8: =D8+0.3% -> 0.057753391 | G8: =F8+0.3% -> 0.060753391 | H8: =G8+0.3% -> 0.063753391 | I8: =H8+0.3% -> 0.066753391 | J8: =I8+0.3% -> 0.069753391 | K8: =J8+0.3% -> 0.072753391 | L8: =K8+0.3% -> 0.075753391 | M8: =L8+0.3% -> 0.078753391 | N8: =M8+0.3% -> 0.081753391 | O8: =N8+0.3% -> 0.084753391
B9: Bull Case | D9: =MAX(Model!E12:I12) -> 0.18512278 | F9: 0.12 | G9: =F9+0.1% -> 0.121 | H9: =G9+0.1% -> 0.122 | I9: =H9+0.1% -> 0.123 | J9: =I9+0.1% -> 0.124 | K9: =J9+0.1% -> 0.125 | L9: =K9+0.1% -> 0.126 | M9: =L9+0.1% -> 0.127 | N9: =M9+0.1% -> 0.128 | O9: =N9+0.1% -> 0.129
B10: Bear Case | D10: =MIN(Model!E12:I12) -> -0.044770308 | F10: 0.05 | G10: =F10+0.1% -> 0.051 | H10: =G10+0.1% -> 0.052 | I10: =H10+0.1% -> 0.053 | J10: =I10+0.1% -> 0.054 | K10: =J10+0.1% -> 0.055 | L10: =K10+0.1% -> 0.056 | M10: =L10+0.1% -> 0.057 | N10: =M10+0.1% -> 0.058 | O10: =N10+0.1% -> 0.059
B11: Annual Growth Tapering | D11: 0.095

Sheet P&L
B2: Asian Paints Ltd
B3: ASIANPAINT | 500820
B4: Consolidated Statement of Profit and Loss
B6: Particular | D6: =CF!D6 -> 2022 | E6: =D6+1 -> 2023 | F6: =E6+1 -> 2024 | G6: =F6+1 -> 2025 | H6: =G6+1 -> 2026
B7: All Values In Crores
B9: REVENUE FROM OPERATIONS
B10: Revenue from Sale of Products | D10: 28830.02 | E10: 34253.35 | F10: 35248.88 | G10: 33626.82 | H10: 35416.25
B11: Revenue from Sale of Services | D11: 93.46 | E11: 114.48 | F11: 133.24 | G11: 170.54 | H11: 100.12
B12: Other Operating Revenue | D12: 177.8 | E12: 120.76 | F12: 112.61 | G12: 108.26 | H12: 67.17
B13: Other Income | D13: 380.01 | E13: 386.48 | F13: 687.96 | G13: 572.61 | H13: 723.8
B14: Total Income | D14: =SUM(D10:D13) -> 29481.29 | E14: =SUM(E10:E13) -> 34875.07 | F14: =SUM(F10:F13) -> 36182.69 | G14: =SUM(G10:G13) -> 34478.23 | H14: =SUM(H10:H13) -> 36307.34
B16: EXPENSES
B17: Cost of Materials Consumed | D17: 16254.59 | E17: 17330.58 | F17: 15868.21 | G17: 15793.92 | H17: 15384.05
B18: Purchases of Stock-in-Trade | D18: 3371.13 | E18: 4135.65 | F18: 3858.2 | G18: 3926.86 | H18: 4014.05
B19: Changes in inventories of finished goods, Stock-in-Trade and work-in-progress | D19: -1324.97 | E19: -309.73 | F19: 363.8 | G19: -205 | H19: 603.68
B20: Employee Benefits Expense | D20: 1786.67 | E20: 2028.07 | F20: 2326.18 | G20: 2597.23 | H20: 2799.59
B21: Other Expenses | D21: 4210.25 | E21: 5044.18 | F21: 5493.36 | G21: 5786.4 | H21: 6086.25
B22: Total Expenses | D22: =SUM(D17:D21) -> 24297.67 | E22: =SUM(E17:E21) -> 28228.75 | F22: =SUM(F17:F21) -> 27909.75 | G22: =SUM(G17:G21) -> 27899.41 | H22: =SUM(H17:H21) -> 28887.62
B24: (EBITDA) | D24: =D14-D22 -> 5183.62 | E24: =E14-E22 -> 6646.32 | F24: =F14-F22 -> 8272.94 | G24: =G14-G22 -> 6578.82 | H24: =H14-H22 -> 7419.72
B26: Finance Costs | D26: 95.41 | E26: 144.45 | F26: 205.17 | G26: 227.02 | H26: 195.41
B27: Depreciation and Amortisation Expense | D27: 816.36 | E27: 858.02 | F27: 853 | G27: 1026.34 | H27: 1228.85
B28: PROFIT BEFORE SHARE OF PROFIT IN ASSOCIATES AND EXCEPTIONAL ITEMS | D28: =D24-SUM(D26:D27) -> 4271.85 | E28: =E24-SUM(E26:E27) -> 5643.85 | F28: =F24-SUM(F26:F27) -> 7214.77 | G28: =G24-SUM(G26:G27) -> 5325.46 | H28: =H24-SUM(H26:H27) -> 5995.46
B29: Share of profit in Associates | D29: 31.57 | E29: 93.85 | F29: 133 | G29: 140.71 | H29: 165.59
B30: PROFIT BEFORE EXCEPTIONAL ITEMS AND TAX | D30: =D28+D29 -> 4303.42 | E30: =E28+E29 -> 5737.7 | F30: =F28+F29 -> 7347.77 | G30: =G28+G29 -> 5466.17 | H30: =H28+H29 -> 6161.05
B32: Exceptional Items | D32: 115.7 | E32: 48.87 | F32: 0 | G32: 363.1 | H32: 157.61
B33: PROFIT BEFORE TAX | D33: =D30-D32 -> 4187.72 | E33: =E30-E32 -> 5688.83 | F33: =F30-F32 -> 7347.77 | G33: =G30-G32 -> 5103.07 | H33: =H30-H32 -> 6003.44
B34: Tax Expense
B35: Current Tax | D35: 1161.53 | E35: 1504.14 | F35: 1836 | G35: 1388.98 | H35: 1523.02
B36: Short tax provision for earlier years | D36: 2.82 | E36: 6.64 | F36: -51.35 | G36: -13.39 | H36: 27.05
B37: Deferred Tax | D37: -61.44 | E37: -17.28 | F37: 5.43 | G37: 17.77 | H37: 58.68
B38: Total tax expense | D38: =SUM(D35:D37) -> 1102.91 | E38: =SUM(E35:E37) -> 1493.5 | F38: =SUM(F35:F37) -> 1790.08 | G38: =SUM(G35:G37) -> 1393.36 | H38: =SUM(H35:H37) -> 1608.75
B39: PROFIT AFTER TAX | D39: =D33-D38 -> 3084.81 | E39: =E33-E38 -> 4195.33 | F39: =F33-F38 -> 5557.69 | G39: =G33-G38 -> 3709.71 | H39: =H33-H38 -> 4394.69
B41: OTHER COMPREHENSIVE INCOME (OCI)
B42: A. Items that will not be reclassified to Profit or Loss
B43: (i) (a) Remeasurement of the defined benefit plans | D43: 4.59 | E43: -10.21 | F43: 8.6 | G43: -2.43 | H43: -24.94
B44: (b) Income tax benefit/(expense) on remeasurement of defined benefit plans | D44: -0.96 | E44: 2.62 | F44: -2.17 | G44: 0.16 | H44: 6.17
B45: (ii) (a) Net fair value gain/(loss) on investments in equity instruments through OCI | D45: -82.31 | E45: 90.19 | F45: 7.77 | G45: 273.3 | H45: -22.59
B46: (b) Income tax (expense)/benefit on net fair value gain on investments in equity instruments through OCI | D46: 9.59 | E46: -10.58 | F46: -0.55 | G46: -42.86 | H46: 3.97
B47: (iii) Share of OCI in Associates | D47: -0.05 | E47: -0.77 | F47: -1.19 | G47: -0.43 | H47: -2.77
B48: B. Items that will be reclassified to Profit or Loss
...

Sheet BS
B2: Asian Paints Ltd
B3: ASIANPAINT | 500820
B4: Consolidated Balance Sheet Of Asian Paint
B6: Particular | D6: 2022 | E6: =D6+1 -> 2023 | F6: =E6+1 -> 2024 | G6: =F6+1 -> 2025 | H6: =G6+1 -> 2026
B7: All Values In Crores
B9: ASSETS
B10: Non-Current Assets
B11: Property, Plant and Equipment | D11: 4184.46 | E11: 4145.65 | F11: 4446.2 | G11: 6787.62 | H11: 7146.23
B12: Right-of-Use Assets | D12: 905.75 | E12: 1208.92 | F12: 1856.27 | G12: 1843.72 | H12: 2018.77
B13: Capital work-in-progress | D13: 426.43 | E13: 1019.59 | F13: 2698.37 | G13: 1254.49 | H13: 1848.67
B14: Goodwill | D14: 242.86 | E14: 228.48 | F14: 419.19 | G14: 219.58 | H14: 219.08
B15: Other Intangible Assets | D15: 185.99 | E15: 187.41 | F15: 424.96 | G15: 369.18 | H15: 256.2
B16: Investments in Associates | D16: 515.47 | E16: 781.73 | F16: 583.13 | G16: 608 | H16: 656.09
B17: Financial Assets
B18: Investments | D18: 551.36 | E18: 782.98 | F18: 801.38 | G18: 871.79 | H18: 119.82
B19: Trade Receivables | D19: 2.4 | E19: 2.17 | F19: 1.78 | G19: 8.71 | H19: 5.36
B20: Loans | D20: 0 | E20: 0 | F20: 0 | G20: 0 | H20: 1.57
B21: Other Financial Assets | D21: 486.05 | E21: 363.18 | F21: 606.51 | G21: 877.84 | H21: 1537.79
B22: Deferred Tax Assets (Net) | D22: 26.02 | E22: 18.67 | F22: 23.32 | G22: 16.12 | H22: 15.74
B23: Income Tax Assets (Net) | D23: 172.46 | E23: 189.52 | F23: 198.11 | G23: 221.62 | H23: 248.62
B24: Other Non-Current Assets | D24: 132.87 | E24: 334.54 | F24: 327.81 | G24: 301.02 | H24: 275.91
B25: Total non-current assets | D25: =SUM(D11:D24) -> 7832.12 | E25: =SUM(E11:E24) -> 9262.84 | F25: =SUM(F11:F24) -> 12387.03 | G25: =SUM(G11:G24) -> 13379.69 | H25: =SUM(H11:H24) -> 14349.85
B27: Current Assets
B28: Inventories | D28: 6152.98 | E28: 6210.64 | F28: 5923.41 | G28: 6719.27 | H28: 5743.69
B29: Financial Assets
B30: Investments | D30: 2180.7 | E30: 2697 | F30: 3203.41 | G30: 3244.96 | H30: 6285.83
B31: Trade Receivables | D31: 3871.44 | E31: 4636.94 | F31: 4889.05 | G31: 4313.65 | H31: 4461.8
B32: Cash and Cash Equivalents | D32: 621.72 | E32: 523.1 | F32: 829.34 | G32: 445.28 | H32: 672.83
B33: Other Balances with Banks | D33: 242.61 | E33: 320.72 | F33: 254.67 | G33: 336.7 | H33: 400.85
B34: Loans | D34: 0 | E34: 0 | F34: 0 | G34: 0 | H34: 0.46
B35: Other Financial Assets | D35: 1533.5 | E35: 1592.78 | F35: 1651.35 | G35: 1158.11 | H35: 1822.67
B36: Other Current Assets | D36: 541.25 | E36: 553.98 | F36: 785.83 | G36: 773.71 | H36: 796.51
B37: Assets classified as Held for Sale | D37: 8.13 | E37: 0 | F37: 0 | G37: 0 | H37: 0
B38: Total current assets | D38: =SUM(D28:D37) -> 15152.33 | E38: =SUM(E28:E37) -> 16535.16 | F38: =SUM(F28:F37) -> 17537.06 | G38: =SUM(G28:G37) -> 16991.68 | H38: =SUM(H28:H37) -> 20184.64
B40: Total Assets | D40: =D25+D38 -> 22984.45 | E40: =E25+E38 -> 25798 | F40: =F25+F38 -> 29924.09 | G40: =G25+G38 -> 30371.37 | H40: =H25+H38 -> 34534.49
B42: EQUITY AND LIABILITIES
B43: Equity
B44: Equity Share Capital | D44: 95.92 | E44: 95.92 | F44: 95.92 | G44: 95.92 | H44: 95.92
B45: Other Equity | D45: 13715.64 | E45: 15896.31 | F45: 18632.38 | G45: 19303.89 | H45: 21275.67
B46: Equity attributable to owners of the Company | D46: =SUM(D44:D45) -> 13811.56 | E46: =SUM(E44:E45) -> 15992.23 | F46: =SUM(F44:F45) -> 18728.3 | G46: =SUM(G44:G45) -> 19399.81 | H46: =SUM(H44:H45) -> 21371.59
...

Sheet CF
B2: Asian Paints Ltd
B3: ASIANPAINT | 500820
B4: Consolidated Statement of Cash Flow
B6: Particular | D6: =BS!D6 -> 2022 | E6: =D6+1 -> 2023 | F6: =E6+1 -> 2024 | G6: =F6+1 -> 2025 | H6: =G6+1 -> 2026
B7: All Values In Crores
B9: (A) CASH FLOW FROM OPERATING ACTIVITIES
B10: Profit before tax | D10: 4187.72 | E10: 5688.83 | F10: 7347.77 | G10: 5103.07 | H10: 6003.44
B11: Adjustments for :
B12: Depreciation and amortisation expense | D12: 816.36 | E12: 858.02 | F12: 853 | G12: 1026.34 | H12: 1228.85
B13: (Gain) on disposal of property, plant and equipment and other intangible assets (net) | D13: -44.36 | E13: -11.72 | F13: -2.08 | G13: -3.37 | H13: 3.81
B14: Net gain on modification/ termination of leases | D14: -4.27 | E14: -2.96 | F14: -5.5 | G14: -2.07 | H14: -6.87
B15: Finance costs | D15: 95.41 | E15: 144.45 | F15: 205.17 | G15: 227.02 | H15: 195.41
B16: Allowances for doubtful debts and advances | D16: 57.56 | E16: 63.91 | F16: 116.64 | G16: 245.18 | H16: 5.7
B17: Fair valuation gain on previously held equity interest, pursuant to acquisition of controlling stake in Obgenix Software Private Limited (White Teak) | D17: 0 | E17: 0 | F17: -33.96 | G17: 0
B18: Bad debts written off | D18: 2.15 | E18: 3.44 | F18: 9.2 | G18: 6.06 | H18: 121.95
B19: Interest income | D19: -92.72 | E19: -120.8 | F19: -169.93 | G19: -179.84 | H19: -180.93
B20: Dividend income | D20: -15.16 | E20: -13.48 | F20: -20.16 | G20: -20.64 | H20: -2.13
B21: Share of profit in Associates | D21: -31.57 | E21: -93.85 | F21: -133 | G21: -140.71 | H21: -165.59
B22: Impairment loss on Goodwill in Causeway Lanka | D22: 13.47 | E22: 24.66 | F22: 0 | G22: 223.25 | H22: 93.87
B23: Net gain arising on financial assets measured at fair value through Profit or Loss (FVTPL) | D23: -76.09 | E23: -120.61 | F23: -229.63 | G23: -182.43 | H23: -286.5
B24: Fair valuation loss on earnout, derivatives and gross obligation towards acquisition | D24: 0 | E24: 28.85 | F24: -63.68 | G24: -18.29 | H24: 19.96
B25: Share based payment expense (net) | D25: 10.94 | E25: 13.38 | F25: 21.84 | G25: 21.25 | H25: 29.35
B26: Loss on sale of disposal of subsidiaries | D26: 0 | E26: 0 | F26: 0 | G26: 83.71 | H26: 0
B27: (Reversal)/ Provision for expected credit loss on government grants | D27: 53.73 | E27: -27.58 | F27: -10.9 | G27: -1.78 | H27: 70.17
B28: Deferred income arising from government grant | D28: -1.76 | E28: -1.54 | F28: -5.29 | G28: -4.69 | H28: -4.08
B29: Net unrealised foreign exchange loss | D29: 57.6 | E29: 21.94 | F29: 8 | G29: -11.06 | H29: 2.94
B30: Effect of exchange rates on translation of operating cashflows | D30: -71.61 | E30: 4.88 | F30: 41.11 | G30: 18.66 | H30: 56.93
B31: Subtotal of Adjustments | D31: =SUM(D12:D30) -> 769.68 | E31: =SUM(E12:E30) -> 770.99 | F31: =SUM(F12:F30) -> 580.83 | G31: =SUM(G12:G30) -> 1286.59 | H31: =SUM(H12:H30) -> 1182.84
B33: Operating Profit before working capital changes | D33: =SUM(D10:D30) -> 4957.4 | E33: =SUM(E10:E30) -> 6459.82 | F33: =SUM(F10:F30) -> 7928.6 | G33: =SUM(G10:G30) -> 6389.66 | H33: =SUM(H10:H30) -> 7186.28
B35: Adjustments for :
B36: (Increase) in trade receivables | D36: -1326.48 | E36: -833.94 | F36: -361.89 | G36: 281.8 | H36: -274.01
B37: Decrease/ (Increase) in financial assets | D37: -130.62 | E37: 156.75 | F37: 23.12 | G37: 6.71 | H37: -65.31
B38: (Increase) in inventories | D38: -2354.38 | E38: -55.98 | F38: 314.94 | G38: -805.34 | H38: 975.58
B39: (Increase) in other assets | D39: -21.21 | E39: -26.71 | F39: -260.89 | G39: 1.71 | H39: -86.1
B40: (Decrease)/ Increase in trade payables | D40: 644.02 | E40: -538.97 | F40: 268.58 | G40: -160.41 | H40: 396.07
B41: Increase in other financial liabilities | D41: 237.19 | E41: 441.1 | F41: 16.4 | G41: 82.56 | H41: 386.79
B42: Increase in other liabilities and provisions | D42: 156.26 | E42: 85.64 | F42: 9.79 | G42: 22.79 | H42: 142.7
B44: Cash generated from Operating activities | D44: =SUM(D33:D42) -> 2162.18 | E44: =SUM(E33:E42) -> 5687.71 | F44: =SUM(F33:F42) -> 7938.65 | G44: =SUM(G33:G42) -> 5819.48 | H44: =SUM(H33:H42) -> 8662
B45: Income Tax paid (net of refund) | D45: -1175.69 | E45: -1494.28 | F45: -1835.05 | G45: -1395.52 | H45: -1573.82
B46: Net Cash generated from Operating activities | D46: =SUM(D44:D45) -> 986.49 | E46: =SUM(E44:E45) -> 4193.43 | F46: =SUM(F44:F45) -> 6103.6 | G46: =SUM(G44:G45) -> 4423.96 | H46: =SUM(H44:H45) -> 7088.18
...

Sheet Index Data
B2: Asian Paints Ltd
B3: ASIANPAINT | 500820
B4: Financial Statement & DCF Analysis
C6: Index | E6: Nifty 50 Tri
B7: Date | C7: Close Price
E8: Years | F8: =YEARFRAC(B9,B2495) -> 10.036111
B9: 46255 | C9: 24252
B10: 46254 | C10: 24231.85 | E10: Market Return | F10: =_xlfn.RRI(F8,C2495,C9) -> 0.10740432
B11: 46253 | C11: 24078.3
B12: 46252 | C12: 24154.9
B13: 46251 | C13: 24287.65
B14: 46248 | C14: 24366
B15: 46247 | C15: 24395.85
B16: 46246 | C16: 24435.95
B17: 46245 | C17: 24471.7
B18: 46244 | C18: 24583.8
B19: 46241 | C19: 24570.65
B20: 46240 | C20: 24636
B21: 46239 | C21: 24624.65
B22: 46238 | C22: 24614.9
... B2495: 42590 | C2495: 8711.35

Sheet Company Data
B3: Asian Paints Ltd
B4: ASIANPAINT | 500820
B5: Financial Statement & DCF Analysis
B7: S.No. | C7: Name | D7: CMP Rs. | E7: Mar Cap Rs.Cr. | F7: Debt Rs.Cr. | G7: EV Rs.Cr. | H7: Sales Rs.Cr. | I7: EBITDA | J7: EV / EBITDA | K7: P/E | L7: PAT 12M Rs.Cr. | M7: Cash Rs.Cr. | N7: Cash Beginning Rs.Cr. | O7: OP 12M Rs.Cr. | P7: Tax 12M Rs.Cr. | Q7: Current Tax 12M Rs.Cr. | R7: Tax Rate
B9: 1 | C9: Asian Paints | D9: 2640 | E9: 264590 | F9: 3928.93 | G9: =E9+F9-M9 -> 267445.25 | H9: 37186.93 | I9: 6700 | J9: =G9/I9 -> 39.917201 | K9: 54.25 | L9: 4877.01 | M9: 1073.68 | N9: 3357.42 | O9: 7239.71 | P9: 1753.39 | Q9: 1671.28 | R9: 0.27
B10: 2 | C10: Berger Paints | D10: 524.4 | E10: 60613.92 | F10: 635.13 | G10: =E10+F10-M10 -> 60943.74 | H10: 11880.25 | I10: 1833 | J10: =G10/I10 -> 33.248085 | K10: 53.57 | L10: 1131.43 | M10: 305.31 | N10: 253.95 | O10: 1833.3 | P10: 360.08 | Q10: 374.42 | R10: 0.24
B11: 3 | C11: Kansai Nerolac | D11: 205.85 | E11: 16213.34 | F11: 302.73 | G11: =E11+F11-M11 -> 16290.29 | H11: 8051.91 | I11: 975 | J11: =G11/I11 -> 16.70799 | K11: 28 | L11: 579.07 | M11: 225.78 | N11: 29.6 | O11: 974.6 | P11: 221.14 | Q11: 221.55 | R11: 0.31
B12: 4 | C12: JSW Dulux | D12: 3118.8 | E12: 13529.69 | F12: 79.1 | G12: =E12+F12-M12 -> 13285.09 | H12: 3599.2 | I12: 509 | J12: =G12/I12 -> 26.100373 | K12: 37.46 | L12: 361.15 | M12: 323.7 | N12: 248.2 | O12: 509.2 | P12: 391.7 | Q12: 331.3 | R12: 0.17
B13: 5 | C13: Indigo Paints | D13: 1151.8 | E13: 5272.62 | F13: 18.37 | G13: =E13+F13-M13 -> 5262.44 | H13: 1330.12 | I13: 247 | J13: =G13/I13 -> 21.305425 | K13: 35.21 | L13: 149.75 | M13: 28.55 | N13: 37.09 | O13: 246.72 | P13: 49.88 | Q13: 47.16 | R13: 0.26
B14: 6 | C14: Sirca Paints | D14: 451.2 | E14: 2284.76 | F14: 32.32 | G14: =E14+F14-M14 -> 2259.1 | H14: 508.26 | I14: 99 | J14: =G14/I14 -> 22.819192 | K14: 34.08 | L14: 67.05 | M14: 57.98 | N14: 43.24 | O14: 100.37 | P14: 22.99 | Q14: 23.01 | R14: 0.25
B15: 7 | C15: Shalimar Paints | D15: 80.89 | E15: 579.38 | F15: 164.76 | G15: =E15+F15-M15 -> 697.05 | H15: 575.63 | I15: -22 | J15: =G15/I15 -> -31.684091 | K15: 0 | L15: -60.35 | M15: 47.09 | N15: -23.83 | O15: -22.4 | P15: -0.44 | Q15: 0 | R15: -0.01
C18: Data from screener.in
C19: this data only for refrence
